Workbook

Sheet RTM Final
A1: Módulo | B1: ID Requerimiento | C1: ID Condición | D1: Descripción de condición | E1: ID Caso | F1: Nombre del caso | G1: Técnica aplicada | H1: ID Dato | I1: Datos de entrada | J1: Resultado esperado | K1: Estado ciclo 1 | L1: Estado final | M1: Defecto asociado | N1: Estado del defecto | O1: Observación
A2: REQ001 | B2: REQ001-A | C2: CT-001 | D2: Autenticación y credenciales | E2: TC-REQ001-001 | F2: Inicio de sesión con credenciales válidas | G2: Partición de equivalencia | H2: TD-001 | I2: Correo: admin.qa@example.com Contraseña: QaSegura123 Rol: Administrador Estado: Activo | J2: Autentica y permite acceso a funcionalidades autorizadas. | K2: =INDEX('Log de Ejecución'!$J$2:$J$41,MATCH($E2,'Log de Ejecución'!$A$2:$A$41,0)) -> Pass | L2: =INDEX('Log de Ejecución'!$O$2:$O$41,MATCH($E2,'Log de Ejecución'!$A$2:$A$41,0)) -> Pass | M2: =INDEX('Log de Ejecución'!$N$2:$N$41,MATCH($E2,'Log de Ejecución'!$A$2:$A$41,0)) -> No registrado | N2: =IFERROR(INDEX('Bug Tracker'!$H$2:$H$200,MATCH(M2,'Bug Tracker'!$A$2:$A$200,0)),"—") -> —
A3: REQ001 | B3: REQ001-A | C3: CT-001 | D3: Autenticación y credenciales | E3: TC-REQ001-002 | F3: Inicio de sesión con contraseña incorrecta | G3: Partición de equivalencia | H3: TD-002 | I3: Correo: admin.qa@example.com Contraseña: Incorrecta123 Rol: Administrador | J3: Rechaza autenticación, no crea sesión y bloquea módulos protegidos. | K3: =INDEX('Log de Ejecución'!$J$2:$J$41,MATCH($E3,'Log de Ejecución'!$A$2:$A$41,0)) -> Pass | L3: =INDEX('Log de Ejecución'!$O$2:$O$41,MATCH($E3,'Log de Ejecución'!$A$2:$A$41,0)) -> Pass | M3: =INDEX('Log de Ejecución'!$N$2:$N$41,MATCH($E3,'Log de Ejecución'!$A$2:$A$41,0)) -> No registrado | N3: =IFERROR(INDEX('Bug Tracker'!$H$2:$H$200,MATCH(M3,'Bug Tracker'!$A$2:$A$200,0)),"—") -> —
A4: REQ001 | B4: REQ001-A | C4: CT-002 | D4: Permisos según rol | E4: TC-REQ001-003 | F4: Acceso permitido según rol de usuario | G4: Tabla de decisión | H4: TD-003 | I4: Correo: admin.qa@example.com Rol: Administrador Operación: Consultar usuarios Permiso: Permitido | J4: Autoriza operación y muestra listado según permisos oficiales. | K4: =INDEX('Log de Ejecución'!$J$2:$J$41,MATCH($E4,'Log de Ejecución'!$A$2:$A$41,0)) -> Pass | L4: =INDEX('Log de Ejecución'!$O$2:$O$41,MATCH($E4,'Log de Ejecución'!$A$2:$A$41,0)) -> Pass | M4: =INDEX('Log de Ejecución'!$N$2:$N$41,MATCH($E4,'Log de Ejecución'!$A$2:$A$41,0)) -> No registrado | N4: =IFERROR(INDEX('Bug Tracker'!$H$2:$H$200,MATCH(M4,'Bug Tracker'!$A$2:$A$200,0)),"—") -> — | O4: Aclaración de diseño: Confirmar matriz de permisos oficial.
A5: REQ001 | B5: REQ001-A | C5: CT-002 | D5: Permisos según rol | E5: TC-REQ001-004 | F5: Acceso denegado a módulo no autorizado | G5: Tabla de decisión | H5: TD-004 | I5: Correo: piloto.qa@example.com Rol: Piloto Operación: Consultar usuarios Permiso: Denegado | J5: API responde HTTP 403 sin revelar datos administrativos. | K5: =INDEX('Log de Ejecución'!$J$2:$J$41,MATCH($E5,'Log de Ejecución'!$A$2:$A$41,0)) -> Pass | L5: =INDEX('Log de Ejecución'!$O$2:$O$41,MATCH($E5,'Log de Ejecución'!$A$2:$A$41,0)) -> Pass | M5: =INDEX('Log de Ejecución'!$N$2:$N$41,MATCH($E5,'Log de Ejecución'!$A$2:$A$41,0)) -> No registrado | N5: =IFERROR(INDEX('Bug Tracker'!$H$2:$H$200,MATCH(M5,'Bug Tracker'!$A$2:$A$200,0)),"—") -> — | O5: Aclaración de diseño: Confirmar matriz de permisos oficial.
A6: REQ001 | B6: REQ001-B | C6: CT-003 | D6: Duplicidad en catálogos | E6: TC-REQ001-005 | F6: Registro duplicado en catálogo de clientes | G6: Partición de equivalencia | H6: TD-005 | I6: Nombre: Cliente QA Duplicado NIT: 1234567-8 Registro previo: mismo NIT | J6: Rechaza duplicado; conserva un solo registro sin modificar original. | K6: =INDEX('Log de Ejecución'!$J$2:$J$41,MATCH($E6,'Log de Ejecución'!$A$2:$A$41,0)) -> Fail | L6: =INDEX('Log de Ejecución'!$O$2:$O$41,MATCH($E6,'Log de Ejecución'!$A$2:$A$41,0)) -> Pass | M6: =INDEX('Log de Ejecución'!$N$2:$N$41,MATCH($E6,'Log de Ejecución'!$A$2:$A$41,0)) -> BUG-CLI-01 | N6: =IFERROR(INDEX('Bug Tracker'!$H$2:$H$200,MATCH(M6,'Bug Tracker'!$A$2:$A$200,0)),"—") -> Cerrado | O6: Falló en ciclo 1 (BUG-CLI-01); corregido y verificado en regresión el 20/10/2026.
A7: REQ001 | B7: REQ001-A | C7: CT-011 | D7: Longitud mínima de contraseña | E7: TC-REQ001-006 | F7: Contraseña inferior a longitud mínima | G7: Análisis de valores límite | H7: TD-006 | I7: Contraseña: Ab123 Longitud: 5 Mínimo implementado: 6 | J7: Rechaza contraseña de cinco caracteres y no la guarda. | K7: =INDEX('Log de Ejecución'!$J$2:$J$41,MATCH($E7,'Log de Ejecución'!$A$2:$A$41,0)) -> Pass | L7: =INDEX('Log de Ejecución'!$O$2:$O$41,MATCH($E7,'Log de Ejecución'!$A$2:$A$41,0)) -> Pass | M7: =INDEX('Log de Ejecución'!$N$2:$N$41,MATCH($E7,'Log de Ejecución'!$A$2:$A$41,0)) -> No registrado | N7: =IFERROR(INDEX('Bug Tracker'!$H$2:$H$200,MATCH(M7,'Bug Tracker'!$A$2:$A$200,0)),"—") -> — | O7: Aclaración de diseño: Confirmar política de contraseña.
A8: REQ001 | B8: REQ001-A | C8: CT-011 | D8: Longitud mínima de contraseña | E8: TC-REQ001-007 | F8: Contraseña igual a longitud mínima | G8: Análisis de valores límite | H8: TD-007 | I8: Contraseña: Ab1234 Longitud: 6 Mínimo implementado: 6 | J8: Supera control de longitud; aceptación final depende de otras reglas. | K8: =INDEX('Log de Ejecución'!$J$2:$J$41,MATCH($E8,'Log de Ejecución'!$A$2:$A$41,0)) -> Pass | L8: =INDEX('Log de Ejecución'!$O$2:$O$41,MATCH($E8,'Log de Ejecución'!$A$2:$A$41,0)) -> Pass | M8: =INDEX('Log de Ejecución'!$N$2:$N$41,MATCH($E8,'Log de Ejecución'!$A$2:$A$41,0)) -> No registrado | N8: =IFERROR(INDEX('Bug Tracker'!$H$2:$H$200,MATCH(M8,'Bug Tracker'!$A$2:$A$200,0)),"—") -> — | O8: Aclaración de diseño: Confirmar política de contraseña.
A9: REQ001 | B9: REQ001-A | C9: CT-011 | D9: Longitud mínima de contraseña | E9: TC-REQ001-008 | F9: Contraseña superior a longitud mínima | G9: Análisis de valores límite | H9: TD-008 | I9: Contraseña: Ab12345 Longitud: 7 Mínimo implementado: 6 | J9: Supera control de longitud; no se rechaza exclusivamente por tener 7 caracteres. | K9: =INDEX('Log de Ejecución'!$J$2:$J$41,MATCH($E9,'Log de Ejecución'!$A$2:$A$41,0)) -> Pass | L9: =INDEX('Log de Ejecución'!$O$2:$O$41,MATCH($E9,'Log de Ejecución'!$A$2:$A$41,0)) -> Pass | M9: =INDEX('Log de Ejecución'!$N$2:$N$41,MATCH($E9,'Log de Ejecución'!$A$2:$A$41,0)) -> No registrado | N9: =IFERROR(INDEX('Bug Tracker'!$H$2:$H$200,MATCH(M9,'Bug Tracker'!$A$2:$A$200,0)),"—") -> — | O9: Aclaración de diseño: Confirmar política de contraseña.
A10: REQ002 | B10: REQ002-A | C10: CT-004 | D10: Cálculo de peso neto | E10: TC-REQ002-001 | F10: Cálculo correcto del peso neto | G10: Partición de equivalencia | H10: TD-009 | I10: Lote: LOT-QA-001 Bruto: 25.00 kg Tara: 2.00 kg Neto: 23.00 kg | J10: Registra neto de 23.00 kg (25.00 − 2.00). | K10: =INDEX('Log de Ejecución'!$J$2:$J$41,MATCH($E10,'Log de Ejecución'!$A$2:$A$41,0)) -> Skipped | L10: =INDEX('Log de Ejecución'!$O$2:$O$41,MATCH($E10,'Log de Ejecución'!$A$2:$A$41,0)) -> Skipped | M10: =INDEX('Log de Ejecución'!$N$2:$N$41,MATCH($E10,'Log de Ejecución'!$A$2:$A$41,0)) -> N/A – fuera de alcance | N10: =IFERROR(INDEX('Bug Tracker'!$H$2:$H$200,MATCH(M10,'Bug Tracker'!$A$2:$A$200,0)),"—") -> — | O10: Fuera del alcance de esta versión (captura de tara), por decisión del equipo.
A11: REQ002 | B11: REQ002-A | C11: CT-004 | D11: Cálculo de peso neto | E11: TC-REQ002-002 | F11: Tara superior al peso bruto | G11: Partición de equivalencia | H11: TD-010 | I11: Lote: LOT-QA-002 Bruto: 20 kg Tara: 25 kg Neto matemático: −5 kg | J11: Rechazar tara superior al bruto; regla propuesta pendiente de confirmar. | K11: =INDEX('Log de Ejecución'!$J$2:$J$41,MATCH($E11,'Log de Ejecución'!$A$2:$A$41,0)) -> Fail | L11: =INDEX('Log de Ejecución'!$O$2:$O$41,MATCH($E11,'Log de Ejecución'!$A$2:$A$41,0)) -> Pass | M11: =INDEX('Log de Ejecución'!$N$2:$N$41,MATCH($E11,'Log de Ejecución'!$A$2:$A$41,0)) -> BUG-REC-01 | N11: =IFERROR(INDEX('Bug Tracker'!$H$2:$H$200,MATCH(M11,'Bug Tracker'!$A$2:$A$200,0)),"—") -> Cerrado | O11: Falló en ciclo 1 (BUG-REC-01); corregido y verificado en regresión el 20/10/2026.
A12: REQ002 | B12: REQ002-B | C12: CT-005 | D12: Umbral de maduración Brix | E12: TC-REQ002-003 | F12: Maduración inferior al umbral | G12: Análisis de valores límite | H12: TD-011 | I12: Sublote: SUB-QA-001 Medición: 21 Brix Umbral: 22 Brix | J12: No promociona automáticamente a Listo para Producción. | K12: =INDEX('Log de Ejecución'!$J$2:$J$41,MATCH($E12,'Log de Ejecución'!$A$2:$A$41,0)) -> Pass | L12: =INDEX('Log de Ejecución'!$O$2:$O$41,MATCH($E12,'Log de Ejecución'!$A$2:$A$41,0)) -> Pass | M12: =INDEX('Log de Ejecución'!$N$2:$N$41,MATCH($E12,'Log de Ejecución'!$A$2:$A$41,0)) -> No registrado | N12: =IFERROR(INDEX('Bug Tracker'!$H$2:$H$200,MATCH(M12,'Bug Tracker'!$A$2:$A$200,0)),"—") -> —
A13: REQ002 | B13: REQ002-B | C13: CT-005 | D13: Umbral de maduración Brix | E13: TC-REQ002-004 | F13: Maduración igual al umbral | G13: Análisis de valores límite | H13: TD-012 | I13: Sublote: SUB-QA-002 Medición: 22 Brix Umbral: 22 Brix | J13: Promociona si se satisfacen las demás condiciones. | K13: =INDEX('Log de Ejecución'!$J$2:$J$41,MATCH($E13,'Log de Ejecución'!$A$2:$A$41,0)) -> Pass | L13: =INDEX('Log de Ejecución'!$O$2:$O$41,MATCH($E13,'Log de Ejecución'!$A$2:$A$41,0)) -> Pass | M13: =INDEX('Log de Ejecución'!$N$2:$N$41,MATCH($E13,'Log de Ejecución'!$A$2:$A$41,0)) -> No registrado | N13: =IFERROR(INDEX('Bug Tracker'!$H$2:$H$200,MATCH(M13,'Bug Tracker'!$A$2:$A$200,0)),"—") -> — | O13: Aclaración de diseño: Conciliar umbral configurable con rango documentado.
A14: REQ002 | B14: REQ002-B | C14: CT-005 | D14: Umbral de maduración Brix | E14: TC-REQ002-005 | F14: Maduración superior al umbral | G14: Análisis de valores límite | H14: TD-013 | I14: Sublote: SUB-QA-003 Medición: 23 Brix Umbral: 22 Brix | J14: Promociona al superar umbral, sujeto a demás condiciones. | K14: =INDEX('Log de Ejecución'!$J$2:$J$41,MATCH($E14,'Log de Ejecución'!$A$2:$A$41,0)) -> Pass | L14: =INDEX('Log de Ejecución'!$O$2:$O$41,MATCH($E14,'Log de Ejecución'!$A$2:$A$41,0)) -> Pass | M14: =INDEX('Log de Ejecución'!$N$2:$N$41,MATCH($E14,'Log de Ejecución'!$A$2:$A$41,0)) -> No registrado | N14: =IFERROR(INDEX('Bug Tracker'!$H$2:$H$200,MATCH(M14,'Bug Tracker'!$A$2:$A$200,0)),"—") -> — | O14: Aclaración de diseño: Conciliar umbral configurable con rango documentado.
A15: REQ002 | B15: REQ002-A | C15: CT-012 | D15: Acumulación de pesos por cajas | E15: TC-REQ002-006 | F15: Acumulación de peso neto por cajas | G15: Partición de equivalencia | H15: TD-014 | I15: Lote: LOT-QA-003 C1: 20−2=18 kg C2: 25−2=23 kg C3: 30−3=27 kg Total: 68 kg | J15: Netos 18, 23 y 27 kg; acumulado neto 68 kg y bruto 75 kg. | K15: =INDEX('Log de Ejecución'!$J$2:$J$41,MATCH($E15,'Log de Ejecución'!$A$2:$A$41,0)) -> Skipped | L15: =INDEX('Log de Ejecución'!$O$2:$O$41,MATCH($E15,'Log de Ejecución'!$A$2:$A$41,0)) -> Skipped | M15: =INDEX('Log de Ejecución'!$N$2:$N$41,MATCH($E15,'Log de Ejecución'!$A$2:$A$41,0)) -> N/A – fuera de alcance | N15: =IFERROR(INDEX('Bug Tracker'!$H$2:$H$200,MATCH(M15,'Bug Tracker'!$A$2:$A$200,0)),"—") -> — | O15: Fuera del alcance de esta versión (captura de tara), por decisión del equipo.
A16: REQ002 | B16: REQ002-B | C16: CT-013 | D16: Transición de maduración | E16: TC-REQ002-007 | F16: Transición a Listo para Producción | G16: Transición de estados | H16: TD-015 | I16: Sublote: SUB-QA-004 Estado inicial: En Maduración (por confirmar) Mediciones: 21 y 22 Brix | J16: No promociona con 21; promociona con 22 si corresponde. Confirmar nomenclatura. | K16: =INDEX('Log de Ejecución'!$J$2:$J$41,MATCH($E16,'Log de Ejecución'!$A$2:$A$41,0)) -> Pass | L16: =INDEX('Log de Ejecución'!$O$2:$O$41,MATCH($E16,'Log de Ejecución'!$A$2:$A$41,0)) -> Pass | M16: =INDEX('Log de Ejecución'!$N$2:$N$41,MATCH($E16,'Log de Ejecución'!$A$2:$A$41,0)) -> No registrado | N16: =IFERROR(INDEX('Bug Tracker'!$H$2:$H$200,MATCH(M16,'Bug Tracker'!$A$2:$A$200,0)),"—") -> — | O16: Aclaración de diseño: Confirmar estados y condiciones de promoción.
A17: REQ002 | B17: REQ002-B | C17: CT-013 | D17: Transición de maduración | E17: TC-REQ002-008 | F17: Prevención de promoción prematura | G17: Transición de estados | H17: TD-016 | I17: Sublote: SUB-QA-005 Medición: 20 Brix Umbral: 22 Brix | J17: No cambia automáticamente a Listo para Producción. | K17: =INDEX('Log de Ejecución'!$J$2:$J$41,MATCH($E17,'Log de Ejecución'!$A$2:$A$41,0)) -> Pass | L17: =INDEX('Log de Ejecución'!$O$2:$O$41,MATCH($E17,'Log de Ejecución'!$A$2:$A$41,0)) -> Pass | M17: =INDEX('Log de Ejecución'!$N$2:$N$41,MATCH($E17,'Log de Ejecución'!$A$2:$A$41,0)) -> No registrado | N17: =IFERROR(INDEX('Bug Tracker'!$H$2:$H$200,MATCH(M17,'Bug Tracker'!$A$2:$A$200,0)),"—") -> — | O17: Aclaración de diseño: Confirmar estados y condiciones de promoción.
A18: REQ003 | B18: REQ003-A | C18: CT-006 | D18: Registro de etapas y mermas | E18: TC-REQ003-001 | F18: Registro correcto de etapa de producción | G18: Partición de equivalencia | H18: TD-017 | I18: Lote: LOT-QA-P001 Etapa: Pelado Entrada: 100 kg Salida: 90 kg Merma: 10 kg Responsable: OPER-QA-01 | J18: Registra etapa, pesos, merma y personal responsable. | K18: =INDEX('Log de Ejecución'!$J$2:$J$41,MATCH($E18,'Log de Ejecución'!$A$2:$A$41,0)) -> Pass | L18: =INDEX('Log de Ejecución'!$O$2:$O$41,MATCH($E18,'Log de Ejecución'!$A$2:$A$41,0)) -> Pass | M18: =INDEX('Log de Ejecución'!$N$2:$N$41,MATCH($E18,'Log de Ejecución'!$A$2:$A$41,0)) -> No registrado | N18: =IFERROR(INDEX('Bug Tracker'!$H$2:$H$200,MATCH(M18,'Bug Tracker'!$A$2:$A$200,0)),"—") -> —
A19: REQ003 | B19: REQ003-A | C19: CT-006 | D19: Registro de etapas y mermas | E19: TC-REQ003-002 | F19: Merma superior al peso de entrada | G19: Partición de equivalencia | H19: TD-018 | I19: Lote: LOT-QA-P002 Etapa: Corte Entrada: 50 kg Salida: 0 kg Merma: 60 kg | J19: Rechazar inconsistencia física; regla pendiente de validación de negocio. | K19: =INDEX('Log de Ejecución'!$J$2:$J$41,MATCH($E19,'Log de Ejecución'!$A$2:$A$41,0)) -> Fail | L19: =INDEX('Log de Ejecución'!$O$2:$O$41,MATCH($E19,'Log de Ejecución'!$A$2:$A$41,0)) -> Pass | M19: =INDEX('Log de Ejecución'!$N$2:$N$41,MATCH($E19,'Log de Ejecución'!$A$2:$A$41,0)) -> BUG-PRO-01 | N19: =IFERROR(INDEX('Bug Tracker'!$H$2:$H$200,MATCH(M19,'Bug Tracker'!$A$2:$A$200,0)),"—") -> Cerrado | O19: Falló en ciclo 1 (BUG-PRO-01); corregido y verificado en regresión el 20/10/2026.
A20: REQ003 | B20: REQ003-B | C20: CT-007 | D20: Balance de masa y cierre | E20: TC-REQ003-003 | F20: Cierre con balance correcto | G20: Tabla de decisión | H20: TD-019 | I20: Proceso: PROD-QA-003 Entrada: 100 kg Merma: 15 kg Producido: 85 kg Diferencia: 0 | J20: Permite cierre: 100 − 15 = 85 kg. | K20: =INDEX('Log de Ejecución'!$J$2:$J$41,MATCH($E20,'Log de Ejecución'!$A$2:$A$41,0)) -> Pass | L20: =INDEX('Log de Ejecución'!$O$2:$O$41,MATCH($E20,'Log de Ejecución'!$A$2:$A$41,0)) -> Pass | M20: =INDEX('Log de Ejecución'!$N$2:$N$41,MATCH($E20,'Log de Ejecución'!$A$2:$A$41,0)) -> No registrado | N20: =IFERROR(INDEX('Bug Tracker'!$H$2:$H$200,MATCH(M20,'Bug Tracker'!$A$2:$A$200,0)),"—") -> —
A21: REQ003 | B21: REQ003-B | C21: CT-007 | D21: Balance de masa y cierre | E21: TC-REQ003-004 | F21: Cierre con diferencia sin justificación | G21: Tabla de decisión | H21: TD-020 | I21: Proceso: PROD-QA-004 Entrada: 100 kg Merma: 10 kg Producido: 85 kg Diferencia: 5 kg Justificación: Vacía | J21: Rechaza cierre; proceso permanece abierto. | K21: =INDEX('Log de Ejecución'!$J$2:$J$41,MATCH($E21,'Log de Ejecución'!$A$2:$A$41,0)) -> Pass | L21: =INDEX('Log de Ejecución'!$O$2:$O$41,MATCH($E21,'Log de Ejecución'!$A$2:$A$41,0)) -> Pass | M21: =INDEX('Log de Ejecución'!$N$2:$N$41,MATCH($E21,'Log de Ejecución'!$A$2:$A$41,0)) -> No registrado | N21: =IFERROR(INDEX('Bug Tracker'!$H$2:$H$200,MATCH(M21,'Bug Tracker'!$A$2:$A$200,0)),"—") -> —
A22: REQ003 | B22: REQ003-B | C22: CT-007 | D22: Balance de masa y cierre | E22: TC-REQ003-005 | F22: Cierre con diferencia justificada | G22: Tabla de decisión | H22: TD-021 | I22: Proceso: PROD-QA-005 Entrada: 100 kg Merma: 10 kg Producido: 85 kg Diferencia: 5 kg Justificación: Diferencia en pesaje manual. | J22: Ruta alternativa permite cierre con justificación explícita; autorización pendiente de confirmar. | K22: =INDEX('Log de Ejecución'!$J$2:$J$41,MATCH($E22,'Log de Ejecución'!$A$2:$A$41,0)) -> Pass | L22: =INDEX('Log de Ejecución'!$O$2:$O$41,MATCH($E22,'Log de Ejecución'!$A$2:$A$41,0)) -> Pass | M22: =INDEX('Log de Ejecución'!$N$2:$N$41,MATCH($E22,'Log de Ejecución'!$A$2:$A$41,0)) -> No registrado | N22: =IFERROR(INDEX('Bug Tracker'!$H$2:$H$200,MATCH(M22,'Bug Tracker'!$A$2:$A$200,0)),"—") -> — | O22: Aclaración de diseño: Confirmar autorización para justificar diferencia.
A23: REQ003 | B23: REQ003-B | C23: CT-015 | D23: Diferencia mínima de peso | E23: TC-REQ003-006 | F23: Balance con diferencia mínima | G23: Análisis de valores límite | H23: TD-022 | I23: Proceso: PROD-QA-006 Entrada: 100.00 kg Merma: 10.00 kg Producido: 89.99 kg Diferencia: 0.01 kg | J23: Si no existe tolerancia, rechaza cierre; tolerancias pendientes de confirmar. | K23: =INDEX('Log de Ejecución'!$J$2:$J$41,MATCH($E23,'Log de Ejecución'!$A$2:$A$41,0)) -> Pass | L23: =INDEX('Log de Ejecución'!$O$2:$O$41,MATCH($E23,'Log de Ejecución'!$A$2:$A$41,0)) -> Pass | M23: =INDEX('Log de Ejecución'!$N$2:$N$41,MATCH($E23,'Log de Ejecución'!$A$2:$A$41,0)) -> No registrado | N23: =IFERROR(INDEX('Bug Tracker'!$H$2:$H$200,MATCH(M23,'Bug Tracker'!$A$2:$A$200,0)),"—") -> — | O23: Aclaración de diseño: Confirmar tolerancia y precisión del balance.
A24: REQ003 | B24: REQ003-A | C24: CT-014 | D24: Merma igual a peso de entrada | E24: TC-REQ003-007 | F24: Merma igual al peso de entrada | G24: Análisis de valores límite | H24: TD-023 | I24: Lote: LOT-QA-P007 Etapa: Corte Entrada: 50 kg Merma: 50 kg Salida: 0 kg | J24: No produce negativos ni errores; aceptación del rendimiento 0% por confirmar. | K24: =INDEX('Log de Ejecución'!$J$2:$J$41,MATCH($E24,'Log de Ejecución'!$A$2:$A$41,0)) -> Pass | L24: =INDEX('Log de Ejecución'!$O$2:$O$41,MATCH($E24,'Log de Ejecución'!$A$2:$A$41,0)) -> Pass | M24: =INDEX('Log de Ejecución'!$N$2:$N$41,MATCH($E24,'Log de Ejecución'!$A$2:$A$41,0)) -> No registrado | N24: =IFERROR(INDEX('Bug Tracker'!$H$2:$H$200,MATCH(M24,'Bug Tracker'!$A$2:$A$200,0)),"—") -> — | O24: Aclaración de diseño: Confirmar tratamiento de rendimiento cero.
A25: REQ003 | B25: REQ003-B | C25: CT-016 | D25: Justificación vacía | E25: TC-REQ003-008 | F25: Justificación compuesta solo por espacios | G25: Tabla de decisión | H25: TD-024 | I25: Proceso: PROD-QA-008 Entrada: 200 kg Merma: 20 kg Producido: 175 kg Diferencia: 5 kg Justificación: " " | J25: Trata espacios como vacío y rechaza cierre; regla propuesta por confirmar. | K25: =INDEX('Log de Ejecución'!$J$2:$J$41,MATCH($E25,'Log de Ejecución'!$A$2:$A$41,0)) -> Fail | L25: =INDEX('Log de Ejecución'!$O$2:$O$41,MATCH($E25,'Log de Ejecución'!$A$2:$A$41,0)) -> Pass | M25: =INDEX('Log de Ejecución'!$N$2:$N$41,MATCH($E25,'Log de Ejecución'!$A$2:$A$41,0)) -> BUG-PRO-02 | N25: =IFERROR(INDEX('Bug Tracker'!$H$2:$H$200,MATCH(M25,'Bug Tracker'!$A$2:$A$200,0)),"—") -> Cerrado | O25: Falló en ciclo 1 (BUG-PRO-02); corregido y verificado en regresión el 20/10/2026.
A26: REQ004 | B26: REQ004-A | C26: CT-008 | D26: Disponibilidad de vehículo y piloto | E26: TC-REQ004-001 | F26: Ruta con vehículo y piloto disponibles | G26: Tabla de decisión | H26: TD-025 | I26: Ruta: RUT-QA-001 Pedido: PED-QA-001 Vehículo: VEH-QA-01 (Disponible) Piloto: PIL-QA-01 (sin ruta) Fecha: 2026-10-12 | J26: Crea ruta con pedido, vehículo y piloto asociados. | K26: =INDEX('Log de Ejecución'!$J$2:$J$41,MATCH($E26,'Log de Ejecución'!$A$2:$A$41,0)) -> Pass | L26: =INDEX('Log de Ejecución'!$O$2:$O$41,MATCH($E26,'Log de Ejecución'!$A$2:$A$41,0)) -> Pass | M26: =INDEX('Log de Ejecución'!$N$2:$N$41,MATCH($E26,'Log de Ejecución'!$A$2:$A$41,0)) -> No registrado | N26: =IFERROR(INDEX('Bug Tracker'!$H$2:$H$200,MATCH(M26,'Bug Tracker'!$A$2:$A$200,0)),"—") -> —
A27: REQ004 | B27: REQ004-A | C27: CT-008 | D27: Disponibilidad de vehículo y piloto | E27: TC-REQ004-002 | F27: Rechazo de vehículo no disponible | G27: Tabla de decisión | H27: TD-026 | I27: Ruta: RUT-QA-002 Pedido: PED-QA-002 Vehículo: VEH-QA-02 (No disponible) Piloto: PIL-QA-02 | J27: Rechaza asignación y no crea ruta activa. | K27: =INDEX('Log de Ejecución'!$J$2:$J$41,MATCH($E27,'Log de Ejecución'!$A$2:$A$41,0)) -> Pass | L27: =INDEX('Log de Ejecución'!$O$2:$O$41,MATCH($E27,'Log de Ejecución'!$A$2:$A$41,0)) -> Pass | M27: =INDEX('Log de Ejecución'!$N$2:$N$41,MATCH($E27,'Log de Ejecución'!$A$2:$A$41,0)) -> No registrado | N27: =IFERROR(INDEX('Bug Tracker'!$H$2:$H$200,MATCH(M27,'Bug Tracker'!$A$2:$A$200,0)),"—") -> —
A28: REQ004 | B28: REQ004-B | C28: CT-009 | D28: Kilometraje y devoluciones | E28: TC-REQ004-003 | F28: Kilometraje de llegada válido | G28: Partición de equivalencia | H28: TD-027 | I28: Ruta: RUT-QA-003 Salida: 15000 km Llegada: 15125 km Recorrido: 125 km | J28: Acepta llegada y registra recorrido de 125 km. | K28: =INDEX('Log de Ejecución'!$J$2:$J$41,MATCH($E28,'Log de Ejecución'!$A$2:$A$41,0)) -> Pass | L28: =INDEX('Log de Ejecución'!$O$2:$O$41,MATCH($E28,'Log de Ejecución'!$A$2:$A$41,0)) -> Pass | M28: =INDEX('Log de Ejecución'!$N$2:$N$41,MATCH($E28,'Log de Ejecución'!$A$2:$A$41,0)) -> No registrado | N28: =IFERROR(INDEX('Bug Tracker'!$H$2:$H$200,MATCH(M28,'Bug Tracker'!$A$2:$A$200,0)),"—") -> —
A29: REQ004 | B29: REQ004-B | C29: CT-009 | D29: Kilometraje y devoluciones | E29: TC-REQ004-004 | F29: Kilometraje de llegada igual a salida | G29: Análisis de valores límite | H29: TD-028 | I29: Ruta: RUT-QA-004 Salida: 20000 km Llegada: 20000 km Diferencia: 0 | J29: Rechaza llegada porque debe ser estrictamente mayor. | K29: =INDEX('Log de Ejecución'!$J$2:$J$41,MATCH($E29,'Log de Ejecución'!$A$2:$A$41,0)) -> Pass | L29: =INDEX('Log de Ejecución'!$O$2:$O$41,MATCH($E29,'Log de Ejecución'!$A$2:$A$41,0)) -> Pass | M29: =INDEX('Log de Ejecución'!$N$2:$N$41,MATCH($E29,'Log de Ejecución'!$A$2:$A$41,0)) -> No registrado | N29: =IFERROR(INDEX('Bug Tracker'!$H$2:$H$200,MATCH(M29,'Bug Tracker'!$A$2:$A$200,0)),"—") -> —
A30: REQ004 | B30: REQ004-A | C30: CT-017 | D30: Doble asignación de piloto | E30: TC-REQ004-005 | F30: Piloto con otra ruta activa | G30: Tabla de decisión | H30: TD-029 | I30: Ruta existente: RUT-QA-005A Nueva: RUT-QA-005B Piloto: PIL-QA-03 (ocupado) Vehículo: VEH-QA-03 | J30: Impide segunda ruta activa para el mismo piloto. | K30: =INDEX('Log de Ejecución'!$J$2:$J$41,MATCH($E30,'Log de Ejecución'!$A$2:$A$41,0)) -> Pass | L30: =INDEX('Log de Ejecución'!$O$2:$O$41,MATCH($E30,'Log de Ejecución'!$A$2:$A$41,0)) -> Pass | M30: =INDEX('Log de Ejecución'!$N$2:$N$41,MATCH($E30,'Log de Ejecución'!$A$2:$A$41,0)) -> No registrado | N30: =IFERROR(INDEX('Bug Tracker'!$H$2:$H$200,MATCH(M30,'Bug Tracker'!$A$2:$A$200,0)),"—") -> —
A31: REQ004 | B31: REQ004-B | C31: CT-018 | D31: Kilometraje inferior a salida | E31: TC-REQ004-006 | F31: Kilometraje de llegada inferior | G31: Análisis de valores límite | H31: TD-030 | I31: Ruta: RUT-QA-006 Salida: 20000 km Llegada: 19999 km Diferencia: −1 km | J31: Rechaza llegada y no almacena distancia negativa. | K31: =INDEX('Log de Ejecución'!$J$2:$J$41,MATCH($E31,'Log de Ejecución'!$A$2:$A$41,0)) -> Pass | L31: =INDEX('Log de Ejecución'!$O$2:$O$41,MATCH($E31,'Log de Ejecución'!$A$2:$A$41,0)) -> Pass | M31: =INDEX('Log de Ejecución'!$N$2:$N$41,MATCH($E31,'Log de Ejecución'!$A$2:$A$41,0)) -> No registrado | N31: =IFERROR(INDEX('Bug Tracker'!$H$2:$H$200,MATCH(M31,'Bug Tracker'!$A$2:$A$200,0)),"—") -> —
A32: REQ004 | B32: REQ004-B | C32: CT-019 | D32: Recepción y resolución de devoluciones | E32: TC-REQ004-007 | F32: Devolución con recepción física | G32: Transición de estados | H32: TD-031 | I32: Ruta: RUT-QA-007 Producto: PROD-QA-01 Cantidad: 5 Recepción: Confirmada Resolución: Pendiente | J32: Registra recepción y trazabilidad; resolución pendiente. Nombre del estado por confirmar. | K32: =INDEX('Log de Ejecución'!$J$2:$J$41,MATCH($E32,'Log de Ejecución'!$A$2:$A$41,0)) -> Pass | L32: =INDEX('Log de Ejecución'!$O$2:$O$41,MATCH($E32,'Log de Ejecución'!$A$2:$A$41,0)) -> Pass | M32: =INDEX('Log de Ejecución'!$N$2:$N$41,MATCH($E32,'Log de Ejecución'!$A$2:$A$41,0)) -> No registrado | N32: =IFERROR(INDEX('Bug Tracker'!$H$2:$H$200,MATCH(M32,'Bug Tracker'!$A$2:$A$200,0)),"—") -> — | O32: Aclaración de diseño: Conciliar estados Devuelto / Con Devolución.
A33: REQ004 | B33: REQ004-B | C33: CT-019 | D33: Recepción y resolución de devoluciones | E33: TC-REQ004-008 | F33: Resolución sin recepción física | G33: Transición de estados | H33: TD-032 | I33: Devolución: DEV-QA-008 Producto: PROD-QA-02 Cantidad: 8 Recepción: No confirmada Resolución: Reingreso | J33: Impide reingreso y no incrementa inventario. | K33: =INDEX('Log de Ejecución'!$J$2:$J$41,MATCH($E33,'Log de Ejecución'!$A$2:$A$41,0)) -> Pass | L33: =INDEX('Log de Ejecución'!$O$2:$O$41,MATCH($E33,'Log de Ejecución'!$A$2:$A$41,0)) -> Pass | M33: =INDEX('Log de Ejecución'!$N$2:$N$41,MATCH($E33,'Log de Ejecución'!$A$2:$A$41,0)) -> No registrado | N33: =IFERROR(INDEX('Bug Tracker'!$H$2:$H$200,MATCH(M33,'Bug Tracker'!$A$2:$A$200,0)),"—") -> — | O33: Aclaración de diseño: Confirmar reglas de resolución de devolución.
A34: REQ005 | B34: REQ005 | C34: CT-010 | D34: Consulta y exportación de reportes | E34: TC-REQ005-001 | F34: Consulta con filtro de fechas | G34: Partición de equivalencia | H34: TD-033 | I34: Reporte: Producción Inicio: 2026-10-01 Fin: 2026-10-07 Dentro: PROD-R01, PROD-R02 Fuera: PROD-R03 | J34: Incluye R01 y R02; excluye R03. | K34: =INDEX('Log de Ejecución'!$J$2:$J$41,MATCH($E34,'Log de Ejecución'!$A$2:$A$41,0)) -> Pass | L34: =INDEX('Log de Ejecución'!$O$2:$O$41,MATCH($E34,'Log de Ejecución'!$A$2:$A$41,0)) -> Pass | M34: =INDEX('Log de Ejecución'!$N$2:$N$41,MATCH($E34,'Log de Ejecución'!$A$2:$A$41,0)) -> No registrado | N34: =IFERROR(INDEX('Bug Tracker'!$H$2:$H$200,MATCH(M34,'Bug Tracker'!$A$2:$A$200,0)),"—") -> —
A35: REQ005 | B35: REQ005 | C35: CT-010 | D35: Consulta y exportación de reportes | E35: TC-REQ005-002 | F35: Exportación PDF sin pérdida | G35: Partición de equivalencia | H35: TD-034 | I35: Reporte: Producción Inicio: 2026-10-01 Fin: 2026-10-07 Registros: 2 Total: 150 kg Formato: PDF | J35: PDF conserva dos registros y total 150 kg. | K35: =INDEX('Log de Ejecución'!$J$2:$J$41,MATCH($E35,'Log de Ejecución'!$A$2:$A$41,0)) -> Pass | L35: =INDEX('Log de Ejecución'!$O$2:$O$41,MATCH($E35,'Log de Ejecución'!$A$2:$A$41,0)) -> Pass | M35: =INDEX('Log de Ejecución'!$N$2:$N$41,MATCH($E35,'Log de Ejecución'!$A$2:$A$41,0)) -> No registrado | N35: =IFERROR(INDEX('Bug Tracker'!$H$2:$H$200,MATCH(M35,'Bug Tracker'!$A$2:$A$200,0)),"—") -> —
A36: REQ005 | B36: REQ005 | C36: CT-010 | D36: Consulta y exportación de reportes | E36: TC-REQ005-003 | F36: Exportación Excel sin pérdida | G36: Partición de equivalencia | H36: TD-035 | I36: Registros: PROD-R01 (100 kg), PROD-R02 (50 kg) Total: 150 kg Formato: Excel | J36: Excel conserva filas, cantidades y total de 150 kg. | K36: =INDEX('Log de Ejecución'!$J$2:$J$41,MATCH($E36,'Log de Ejecución'!$A$2:$A$41,0)) -> Fail | L36: =INDEX('Log de Ejecución'!$O$2:$O$41,MATCH($E36,'Log de Ejecución'!$A$2:$A$41,0)) -> Pass | M36: =INDEX('Log de Ejecución'!$N$2:$N$41,MATCH($E36,'Log de Ejecución'!$A$2:$A$41,0)) -> BUG-REP-01 | N36: =IFERROR(INDEX('Bug Tracker'!$H$2:$H$200,MATCH(M36,'Bug Tracker'!$A$2:$A$200,0)),"—") -> Cerrado | O36: Falló en ciclo 1 (BUG-REP-01); corregido y verificado en regresión el 20/10/2026.
A37: REQ005 | B37: REQ005 | C37: CT-020 | D37: Intervalos de fecha | E37: TC-REQ005-004 | F37: Intervalo de fechas inválido | G37: Análisis de valores límite | H37: TD-036 | I37: Inicio: 2026-10-15 Fin: 2026-10-10 | J37: Rechaza intervalo invertido; regla propuesta por confirmar. | K37: =INDEX('Log de Ejecución'!$J$2:$J$41,MATCH($E37,'Log de Ejecución'!$A$2:$A$41,0)) -> Fail | L37: =INDEX('Log de Ejecución'!$O$2:$O$41,MATCH($E37,'Log de Ejecución'!$A$2:$A$41,0)) -> Pass | M37: =INDEX('Log de Ejecución'!$N$2:$N$41,MATCH($E37,'Log de Ejecución'!$A$2:$A$41,0)) -> BUG-REP-02 | N37: =IFERROR(INDEX('Bug Tracker'!$H$2:$H$200,MATCH(M37,'Bug Tracker'!$A$2:$A$200,0)),"—") -> Cerrado | O37: Falló en ciclo 1 (BUG-REP-02); corregido y verificado en regresión el 20/10/2026.
A38: REQ005 | B38: REQ005 | C38: CT-021 | D38: Combinación Pairwise de filtros | E38: TC-REQ005-005 | F38: Filtros combinados de fecha, cliente y merma | G38: Pairwise | H38: TD-037 | I38: Inicio: 2026-10-01 Fin: 2026-10-07 Cliente: CLI-QA-01 Merma: Pelado Coincide: MER-QA-01 No coincide: MER-QA-02 | J38: Solo muestra registros que cumplen los tres filtros. Variantes PW01–PW04 pendientes de resultados específicos. | K38: =INDEX('Log de Ejecución'!$J$2:$J$41,MATCH($E38,'Log de Ejecución'!$A$2:$A$41,0)) -> Skipped | L38: =INDEX('Log de Ejecución'!$O$2:$O$41,MATCH($E38,'Log de Ejecución'!$A$2:$A$41,0)) -> Skipped | M38: =INDEX('Log de Ejecución'!$N$2:$N$41,MATCH($E38,'Log de Ejecución'!$A$2:$A$41,0)) -> N/A – fuera de alcance | N38: =IFERROR(INDEX('Bug Tracker'!$H$2:$H$200,MATCH(M38,'Bug Tracker'!$A$2:$A$200,0)),"—") -> — | O38: Fuera del alcance de esta versión: ningún reporte combina fecha, cliente y tipo de merma (decisión del equipo).
A39: REQ005 | B39: REQ005 | C39: CT-022 | D39: Consulta sin resultados | E39: TC-REQ005-006 | F39: Reporte sin registros coincidentes | G39: Partición de equivalencia | H39: TD-038 | I39: Inicio: 2026-09-01 Fin: 2026-09-02 Cliente: CLI-QA-99 Registros: 0 | J39: Devuelve cero registros sin mostrar datos ajenos. | K39: =INDEX('Log de Ejecución'!$J$2:$J$41,MATCH($E39,'Log de Ejecución'!$A$2:$A$41,0)) -> Pass | L39: =INDEX('Log de Ejecución'!$O$2:$O$41,MATCH($E39,'Log de Ejecución'!$A$2:$A$41,0)) -> Pass | M39: =INDEX('Log de Ejecución'!$N$2:$N$41,MATCH($E39,'Log de Ejecución'!$A$2:$A$41,0)) -> No registrado | N39: =IFERROR(INDEX('Bug Tracker'!$H$2:$H$200,MATCH(M39,'Bug Tracker'!$A$2:$A$200,0)),"—") -> —
A40: REQ005 | B40: REQ005 | C40: CT-023 | D40: Indicadores de dashboard | E40: TC-REQ005-007 | F40: Consistencia de indicadores dashboard | G40: Partición de equivalencia | H40: TD-039 | I40: Inicio: 2026-10-01 Fin: 2026-10-07 Producción: 100 kg + 50 kg Total supuesto: 150 kg | J40: Si indicador suma kg producidos, muestra 150 kg; fórmula por aprobar. | K40: =INDEX('Log de Ejecución'!$J$2:$J$41,MATCH($E40,'Log de Ejecución'!$A$2:$A$41,0)) -> Pass | L40: =INDEX('Log de Ejecución'!$O$2:$O$41,MATCH($E40,'Log de Ejecución'!$A$2:$A$41,0)) -> Pass | M40: =INDEX('Log de Ejecución'!$N$2:$N$41,MATCH($E40,'Log de Ejecución'!$A$2:$A$41,0)) -> No registrado | N40: =IFERROR(INDEX('Bug Tracker'!$H$2:$H$200,MATCH(M40,'Bug Tracker'!$A$2:$A$200,0)),"—") -> — | O40: Aclaración de diseño: Confirmar fórmula de indicador.
...

Sheet Log de Ejecución
A1: ID Caso | B1: ID REQ | C1: Nombre del Caso | D1: Técnica Aplicada | E1: Prioridad | F1: Precondiciones | G1: Pasos de Ejecución | H1: Datos de Entrada | I1: Resultado Esperado | J1: Estado de ejecución | K1: Fecha de Ejecución | L1: Especialista QA | M1: Resultado obtenido | N1: ID del defecto asociado | O1: Estado final (tras regresión) | P1: Fecha de re-ejecución | Q1: Especialista QA (re-ejecución) | R1: Resultado de la re-ejecución
A2: TC-REQ001-001 | B2: REQ001-A | C2: Inicio de sesión con credenciales válidas | D2: Partición de equivalencia | E2: Alta | F2: Administrador activo creado en QA; servicio de autenticación disponible. | G2: 1. Abrir inicio de sesión. 2. Escribir correo. 3. Escribir contraseña. 4. Pulsar Iniciar sesión. 5. Abrir funcionalidad autorizada. | H2: Correo: admin.qa@example.com Contraseña: QaSegura123 Rol: Administrador Estado: Activo | I2: Autentica y permite acceso a funcionalidades autorizadas. | J2: Pass | K2: 46224 | L2: Samuel Canastuj | M2: Se inició sesión con el administrador activo y se habilitaron sus funciones autorizadas. | N2: No registrado | O2: =J2 -> Pass | R2: No requería re-ejecución (sin defecto asociado).
A3: TC-REQ001-002 | B3: REQ001-A | C3: Inicio de sesión con contraseña incorrecta | D3: Partición de equivalencia | E3: Alta | F3: Administrador activo en QA; sesión cerrada. | G3: 1. Abrir inicio de sesión. 2. Ingresar correo registrado. 3. Ingresar contraseña errónea. 4. Pulsar Iniciar sesión. 5. Intentar entrar a módulo protegido. | H3: Correo: admin.qa@example.com Contraseña: Incorrecta123 Rol: Administrador | I3: Rechaza autenticación, no crea sesión y bloquea módulos protegidos. | J3: Pass | K3: 46225 | L3: Samuel Canastuj | M3: La contraseña incorrecta fue rechazada; no se creó sesión ni se permitió acceso a módulos protegidos. | N3: No registrado | O3: =J3 -> Pass | R3: No requería re-ejecución (sin defecto asociado).
A4: TC-REQ001-003 | B4: REQ001-A | C4: Acceso permitido según rol de usuario | D4: Tabla de decisión | E4: Alta | F4: Administrador activo; permiso de gestión de usuarios confirmado en matriz de permisos. | G4: 1. Autenticarse como Administrador. 2. Abrir Gestión de usuarios. 3. Consultar listado. 4. Revisar respuesta. | H4: Correo: admin.qa@example.com Rol: Administrador Operación: Consultar usuarios Permiso: Permitido | I4: Autoriza operación y muestra listado según permisos oficiales. | J4: Pass | K4: 46225 | L4: Samuel Canastuj | M4: Suponiendo autorizado al rol Administrador, se permitió consultar el listado de usuarios. | N4: No registrado | O4: =J4 -> Pass | R4: No requería re-ejecución (sin defecto asociado).
A5: TC-REQ001-004 | B5: REQ001-A | C5: Acceso denegado a módulo no autorizado | D5: Tabla de decisión | E5: Alta | F5: Piloto activo; consulta administrativa clasificada como no autorizada. | G5: 1. Autenticarse como Piloto. 2. Abrir módulo administrativo. 3. Solicitar endpoint protegido. 4. Revisar código y cuerpo de respuesta. 5. Confirmar ausencia de datos restringidos. | H5: Correo: piloto.qa@example.com Rol: Piloto Operación: Consultar usuarios Permiso: Denegado | I5: API responde HTTP 403 sin revelar datos administrativos. | J5: Pass | K5: 46227 | L5: Samuel Canastuj | M5: Suponiendo que el rol Piloto no tiene ese permiso, la consulta devolvió HTTP 403 sin datos administrativos. | N5: No registrado | O5: =J5 -> Pass | R5: No requería re-ejecución (sin defecto asociado).
A6: TC-REQ001-005 | B6: REQ001-B | C6: Registro duplicado en catálogo de clientes | D6: Partición de equivalencia | E6: Alta | F6: Usuario autorizado; cliente con NIT sintético ya existe en QA. | G6: 1. Abrir catálogo de clientes. 2. Elegir Agregar. 3. Ingresar NIT ya registrado. 4. Guardar. 5. Contar coincidencias del NIT. | H6: Nombre: Cliente QA Duplicado NIT: 1234567-8 Registro previo: mismo NIT | I6: Rechaza duplicado; conserva un solo registro sin modificar original. | J6: Fail | K6: 46227 | L6: Samuel Canastuj | M6: El segundo cliente con NIT 1234567-8 se guardó (HTTP 201); el listado muestra dos clientes activos con el mismo NIT. No existe validación de unicidad. | N6: BUG-CLI-01 | O6: Pass | P6: 46315 | Q6: Samuel Canastuj | R6: Re-ejecutado: el segundo cliente con NIT 1234567-8 fue rechazado (HTTP 409) por API y por la pantalla; solo existe el cliente original.
A7: TC-REQ001-006 | B7: REQ001-A | C7: Contraseña inferior a longitud mínima | D7: Análisis de valores límite | E7: Alta | F7: Formulario de contraseña disponible en QA. | G7: 1. Abrir formulario. 2. Completar campos válidos. 3. Ingresar contraseña de 5 caracteres. 4. Intentar guardar. 5. Revisar validación. | H7: Contraseña: Ab123 Longitud: 5 Mínimo implementado: 6 | I7: Rechaza contraseña de cinco caracteres y no la guarda. | J7: Pass | K7: 46234 | L7: Dennis Cornel | M7: Con un mínimo supuesto de 6 caracteres, la contraseña de 5 se rechazó y no se guardó. | N7: No registrado | O7: =J7 -> Pass | R7: No requería re-ejecución (sin defecto asociado).
A8: TC-REQ001-007 | B8: REQ001-A | C8: Contraseña igual a longitud mínima | D8: Análisis de valores límite | E8: Alta | F8: Formulario disponible; otros campos válidos. | G8: 1. Abrir formulario. 2. Completar campos. 3. Ingresar 6 caracteres. 4. Ejecutar validación. 5. Registrar respuesta. | H8: Contraseña: Ab1234 Longitud: 6 Mínimo implementado: 6 | I8: Supera control de longitud; aceptación final depende de otras reglas. | J8: Pass | K8: 46234 | L8: Dennis Cornel | M8: Con un mínimo supuesto de 6 caracteres, la contraseña de 6 superó el control de longitud. | N8: No registrado | O8: =J8 -> Pass | R8: No requería re-ejecución (sin defecto asociado).
A9: TC-REQ001-008 | B9: REQ001-A | C9: Contraseña superior a longitud mínima | D9: Análisis de valores límite | E9: Alta | F9: Formulario disponible; otros campos válidos. | G9: 1. Abrir formulario. 2. Completar campos. 3. Ingresar 7 caracteres. 4. Ejecutar validación. 5. Registrar respuesta. | H9: Contraseña: Ab12345 Longitud: 7 Mínimo implementado: 6 | I9: Supera control de longitud; no se rechaza exclusivamente por tener 7 caracteres. | J9: Pass | K9: 46240 | L9: Yefferson Valenzuela | M9: Con un mínimo supuesto de 6 caracteres, la contraseña de 7 superó el control de longitud. | N9: No registrado | O9: =J9 -> Pass | R9: No requería re-ejecución (sin defecto asociado).
A10: TC-REQ002-001 | B10: REQ002-A | C10: Cálculo correcto del peso neto | D10: Partición de equivalencia | E10: Alta | F10: Usuario autorizado; proveedor y lote sintéticos creados. | G10: 1. Abrir Recepción. 2. Elegir lote. 3. Registrar bruto y tara. 4. Guardar. 5. Consultar neto. | H10: Lote: LOT-QA-001 Bruto: 25.00 kg Tara: 2.00 kg Neto: 23.00 kg | I10: Registra neto de 23.00 kg (25.00 − 2.00). | J10: Skipped | K10: 46240 | L10: Yefferson Valenzuela | M10: No ejecutado: la captura de peso bruto y tara queda fuera del alcance de esta versión por decisión del equipo; el caso se conserva para una versión futura. | N10: N/A – fuera de alcance | O10: =J10 -> Skipped | R10: No requería re-ejecución (sin defecto asociado).
A11: TC-REQ002-002 | B11: REQ002-A | C11: Tara superior al peso bruto | D11: Partición de equivalencia | E11: Alta | F11: Formulario de recepción y lote QA disponibles. | G11: 1. Abrir recepción. 2. Elegir lote. 3. Registrar bruto 20 kg. 4. Registrar tara 25 kg. 5. Guardar. 6. Revisar que no exista neto negativo. | H11: Lote: LOT-QA-002 Bruto: 20 kg Tara: 25 kg Neto matemático: −5 kg | I11: Rechazar tara superior al bruto; regla propuesta pendiente de confirmar. | J11: Fail | K11: 46244 | L11: Samuel Canastuj | M11: No existe campo de tara; al intentar el equivalente (unidad con peso negativo de −5 kg vía POST /api/entradas-mercancia/{id}/units) la API lo aceptó (HTTP 201) y registró la unidad con peso negativo. | N11: BUG-REC-01 | O11: Pass | P11: 46315 | Q11: Samuel Canastuj | R11: Re-ejecutado: POST /units con peso −5 kg rechazado (HTTP 400); la unidad no se registra.
A12: TC-REQ002-003 | B12: REQ002-B | C12: Maduración inferior al umbral | D12: Análisis de valores límite | E12: Alta | F12: Sublote QA; umbral 22 Brix configurado. | G12: 1. Abrir Maduración. 2. Elegir sublote. 3. Registrar 21 Brix. 4. Guardar. 5. Revisar estado. | H12: Sublote: SUB-QA-001 Medición: 21 Brix Umbral: 22 Brix | I12: No promociona automáticamente a Listo para Producción. | J12: Pass | K12: 46244 | L12: Samuel Canastuj | M12: Con umbral de 22 Brix, registrar 21 Brix mantuvo el sublote sin promover a producción. | N12: No registrado | O12: =J12 -> Pass | R12: No requería re-ejecución (sin defecto asociado).
A13: TC-REQ002-004 | B13: REQ002-B | C13: Maduración igual al umbral | D13: Análisis de valores límite | E13: Alta | F13: Sublote QA; umbral 22; demás condiciones satisfechas. | G13: 1. Abrir Maduración. 2. Elegir sublote. 3. Registrar 22 Brix. 4. Guardar. 5. Revisar estado. | H13: Sublote: SUB-QA-002 Medición: 22 Brix Umbral: 22 Brix | I13: Promociona si se satisfacen las demás condiciones. | J13: Pass | K13: 46248 | L13: Yefferson Valenzuela | M13: Con umbral supuesto de 22 Brix y demás condiciones cumplidas, 22 Brix permitió pasar a Listo para Producción. | N13: No registrado | O13: =J13 -> Pass | R13: No requería re-ejecución (sin defecto asociado).
A14: TC-REQ002-005 | B14: REQ002-B | C14: Maduración superior al umbral | D14: Análisis de valores límite | E14: Alta | F14: Sublote QA; umbral 22; demás condiciones satisfechas. | G14: 1. Abrir Maduración. 2. Elegir sublote. 3. Registrar 23 Brix. 4. Guardar. 5. Revisar estado. | H14: Sublote: SUB-QA-003 Medición: 23 Brix Umbral: 22 Brix | I14: Promociona al superar umbral, sujeto a demás condiciones. | J14: Pass | K14: 46254 | L14: Dennis Cornel | M14: Con umbral supuesto de 22 Brix y demás condiciones cumplidas, 23 Brix permitió pasar a Listo para Producción. | N14: No registrado | O14: =J14 -> Pass | R14: No requería re-ejecución (sin defecto asociado).
A15: TC-REQ002-006 | B15: REQ002-A | C15: Acumulación de peso neto por cajas | D15: Partición de equivalencia | E15: Alta | F15: Lote QA habilitado para varias cajas. | G15: 1. Abrir recepción. 2. Registrar tres cajas. 3. Guardar. 4. Consultar netos y acumulado. | H15: Lote: LOT-QA-003 C1: 20−2=18 kg C2: 25−2=23 kg C3: 30−3=27 kg Total: 68 kg | I15: Netos 18, 23 y 27 kg; acumulado neto 68 kg y bruto 75 kg. | J15: Skipped | K15: 46254 | L15: Dennis Cornel | M15: No ejecutado: depende de la captura de peso bruto y tara por caja, fuera del alcance de esta versión por decisión del equipo; se conserva para una versión futura. | N15: N/A – fuera de alcance | O15: =J15 -> Skipped | R15: No requería re-ejecución (sin defecto asociado).
A16: TC-REQ002-007 | B16: REQ002-B | C16: Transición a Listo para Producción | D16: Transición de estados | E16: Alta | F16: Sublote en maduración; umbral 22; condiciones restantes satisfechas. | G16: 1. Consultar estado inicial. 2. Registrar 21 Brix. 3. Revisar estado. 4. Registrar 22 Brix. 5. Revisar estado final. | H16: Sublote: SUB-QA-004 Estado inicial: En Maduración (por confirmar) Mediciones: 21 y 22 Brix | I16: No promociona con 21; promociona con 22 si corresponde. Confirmar nomenclatura. | J16: Pass | K16: 46258 | L16: Yefferson Valenzuela | M16: Suponiendo umbral de 22 Brix y demás condiciones cumplidas, no se habilitó producción con 21 Brix y sí con 22 Brix. | N16: No registrado | O16: =J16 -> Pass | R16: No requería re-ejecución (sin defecto asociado).
A17: TC-REQ002-008 | B17: REQ002-B | C17: Prevención de promoción prematura | D17: Transición de estados | E17: Alta | F17: Sublote en maduración; umbral 22 Brix. | G17: 1. Abrir maduración. 2. Elegir sublote. 3. Registrar 20 Brix. 4. Guardar. 5. Verificar que no esté listo. | H17: Sublote: SUB-QA-005 Medición: 20 Brix Umbral: 22 Brix | I17: No cambia automáticamente a Listo para Producción. | J17: Pass | K17: 46264 | L17: Samuel Canastuj | M17: Con umbral de 22 Brix, la medición de 20 Brix no activó el paso a producción. | N17: No registrado | O17: =J17 -> Pass | R17: No requería re-ejecución (sin defecto asociado).
A18: TC-REQ003-001 | B18: REQ003-A | C18: Registro correcto de etapa de producción | D18: Partición de equivalencia | E18: Alta | F18: Usuario Producción autorizado; lote y catálogos cargados. | G18: 1. Abrir Control de Producción. 2. Elegir lote y Pelado. 3. Registrar pesos y merma. 4. Asignar responsable. 5. Guardar y consultar. | H18: Lote: LOT-QA-P001 Etapa: Pelado Entrada: 100 kg Salida: 90 kg Merma: 10 kg Responsable: OPER-QA-01 | I18: Registra etapa, pesos, merma y personal responsable. | J18: Pass | K18: 46269 | L18: Dennis Cornel | M18: Se guardó Pelado con entrada de 100 kg, salida de 90 kg, merma de 10 kg y responsable OPER-QA-01. | N18: No registrado | O18: =J18 -> Pass | R18: No requería re-ejecución (sin defecto asociado).
A19: TC-REQ003-002 | B19: REQ003-A | C19: Merma superior al peso de entrada | D19: Partición de equivalencia | E19: Alta | F19: Lote QA y usuario autorizado. | G19: 1. Abrir producción. 2. Elegir Corte. 3. Registrar entrada 50 kg. 4. Registrar merma 60 kg. 5. Guardar. 6. Revisar validación. | H19: Lote: LOT-QA-P002 Etapa: Corte Entrada: 50 kg Salida: 0 kg Merma: 60 kg | I19: Rechazar inconsistencia física; regla pendiente de validación de negocio. | J19: Fail | K19: 46274 | L19: Yefferson Valenzuela | M19: Se registró una merma de 60 kg sobre una etapa con entrada de 50 kg (HTTP 201). La salida de la etapa se ajustó a 0 kg y el balance del proceso quedó en −10 kg sin ningún rechazo. | N19: BUG-PRO-01 | O19: Pass | P19: 46315 | Q19: Yefferson Valenzuela | R19: Re-ejecutado: la merma de 60 kg sobre la etapa Corte de 50 kg se rechaza (HTTP 400) por API y por la pantalla; la etapa no registra la merma.
A20: TC-REQ003-003 | B20: REQ003-B | C20: Cierre con balance correcto | D20: Tabla de decisión | E20: Alta | F20: Proceso abierto y usuario con permiso de cierre. | G20: 1. Abrir proceso. 2. Consultar entrada. 3. Registrar merma y producción. 4. Solicitar cierre. 5. Revisar estado. | H20: Proceso: PROD-QA-003 Entrada: 100 kg Merma: 15 kg Producido: 85 kg Diferencia: 0 | I20: Permite cierre: 100 − 15 = 85 kg. | J20: Pass | K20: 46277 | L20: Dennis Cornel | M20: El proceso cerró con 100 kg de entrada, 15 kg de merma y 85 kg producidos; diferencia: 0 kg. | N20: No registrado | O20: =J20 -> Pass | R20: No requería re-ejecución (sin defecto asociado).
A21: TC-REQ003-004 | B21: REQ003-B | C21: Cierre con diferencia sin justificación | D21: Tabla de decisión | E21: Alta | F21: Proceso abierto; no existe justificación. | G21: 1. Abrir proceso. 2. Registrar entrada, merma y producción. 3. Dejar justificación vacía. 4. Intentar cierre. 5. Revisar estado. | H21: Proceso: PROD-QA-004 Entrada: 100 kg Merma: 10 kg Producido: 85 kg Diferencia: 5 kg Justificación: Vacía | I21: Rechaza cierre; proceso permanece abierto. | J21: Pass | K21: 46279 | L21: Dennis Cornel | M21: Se rechazó el cierre con diferencia de 5 kg y justificación vacía; el proceso continuó abierto. | N21: No registrado | O21: =J21 -> Pass | R21: No requería re-ejecución (sin defecto asociado).
A22: TC-REQ003-005 | B22: REQ003-B | C22: Cierre con diferencia justificada | D22: Tabla de decisión | E22: Alta | F22: Proceso abierto; función de justificación habilitada; permiso por confirmar. | G22: 1. Abrir proceso. 2. Registrar pesos. 3. Identificar diferencia. 4. Escribir justificación. 5. Solicitar cierre. 6. Consultar evidencia guardada. | H22: Proceso: PROD-QA-005 Entrada: 100 kg Merma: 10 kg Producido: 85 kg Diferencia: 5 kg Justificación: Diferencia en pesaje manual. | I22: Ruta alternativa permite cierre con justificación explícita; autorización pendiente de confirmar. | J22: Pass | K22: 46285 | L22: Dennis Cornel | M22: Suponiendo autorización para justificar diferencias, se cerró con diferencia de 5 kg y se conservó la justificación indicada. | N22: No registrado | O22: =J22 -> Pass | R22: No requería re-ejecución (sin defecto asociado).
A23: TC-REQ003-006 | B23: REQ003-B | C23: Balance con diferencia mínima | D23: Análisis de valores límite | E23: Alta | F23: Proceso abierto; precisión de 2 decimales como supuesto. | G23: 1. Abrir proceso. 2. Registrar entrada 100.00. 3. Merma 10.00. 4. Producido 89.99. 5. Cerrar sin justificación. 6. Revisar validación. | H23: Proceso: PROD-QA-006 Entrada: 100.00 kg Merma: 10.00 kg Producido: 89.99 kg Diferencia: 0.01 kg | I23: Si no existe tolerancia, rechaza cierre; tolerancias pendientes de confirmar. | J23: Pass | K23: 46288 | L23: Samuel Canastuj | M23: El sistema tiene definida una tolerancia de balance de 0.01 kg (BALANCE_TOLERANCE_KG); la diferencia de 0.01 kg queda dentro de la tolerancia y el cierre se permitió sin justificación, según la regla vigente. | N23: No registrado | O23: =J23 -> Pass | R23: No requería re-ejecución (sin defecto asociado).
A24: TC-REQ003-007 | B24: REQ003-A | C24: Merma igual al peso de entrada | D24: Análisis de valores límite | E24: Alta | F24: Lote y etapa QA; criterio de rendimiento cero pendiente. | G24: 1. Abrir producción. 2. Elegir lote. 3. Registrar entrada 50. 4. Merma 50. 5. Salida 0. 6. Guardar y revisar. | H24: Lote: LOT-QA-P007 Etapa: Corte Entrada: 50 kg Merma: 50 kg Salida: 0 kg | I24: No produce negativos ni errores; aceptación del rendimiento 0% por confirmar. | J24: Pass | K24: 46288 | L24: Samuel Canastuj | M24: Suponiendo permitido el rendimiento de 0 %, se registraron 50 kg de entrada, 50 kg de merma y 0 kg de salida, sin negativos. | N24: No registrado | O24: =J24 -> Pass | R24: No requería re-ejecución (sin defecto asociado).
A25: TC-REQ003-008 | B25: REQ003-B | C25: Justificación compuesta solo por espacios | D25: Tabla de decisión | E25: Alta | F25: Proceso abierto con diferencia; campo de justificación disponible. | G25: 1. Abrir proceso. 2. Registrar pesos con diferencia. 3. Ingresar tres espacios. 4. Solicitar cierre. 5. Revisar respuesta. | H25: Proceso: PROD-QA-008 Entrada: 200 kg Merma: 20 kg Producido: 175 kg Diferencia: 5 kg Justificación: " " | I25: Trata espacios como vacío y rechaza cierre; regla propuesta por confirmar. | J25: Fail | K25: 46290 | L25: Yefferson Valenzuela | M25: Vía API, el proceso se finalizó (HTTP 200) con diferencia de 5 kg y justificación " " (solo espacios), que quedó guardada como válida. El formulario web sí recorta los espacios; la regla no está protegida en el backend. | N25: BUG-PRO-02 | O25: Pass | P25: 46315 | Q25: Yefferson Valenzuela | R25: Re-ejecutado vía API: la justificación " " se rechaza (HTTP 400); con una justificación real el cierre se acepta (HTTP 200).
A26: TC-REQ004-001 | B26: REQ004-A | C26: Ruta con vehículo y piloto disponibles | D26: Tabla de decisión | E26: Alta | F26: Usuario Logística; vehículo Disponible; piloto sin ruta activa. | G26: 1. Abrir planificación. 2. Elegir pedido. 3. Elegir vehículo. 4. Asignar piloto. 5. Registrar fecha. 6. Guardar y consultar ruta. | H26: Ruta: RUT-QA-001 Pedido: PED-QA-001 Vehículo: VEH-QA-01 (Disponible) Piloto: PIL-QA-01 (sin ruta) Fecha: 2026-10-12 | I26: Crea ruta con pedido, vehículo y piloto asociados. | J26: Pass | K26: 46294 | L26: Yefferson Valenzuela | M26: Se creó RUT-QA-001 para PED-QA-001 con VEH-QA-01 disponible y PIL-QA-01 sin otra ruta activa. | N26: No registrado | O26: =J26 -> Pass | R26: No requería re-ejecución (sin defecto asociado).
A27: TC-REQ004-002 | B27: REQ004-A | C27: Rechazo de vehículo no disponible | D27: Tabla de decisión | E27: Alta | F27: Vehículo no disponible; piloto libre; pedido pendiente. | G27: 1. Abrir planificación. 2. Elegir pedido. 3. Elegir vehículo no disponible. 4. Elegir piloto libre. 5. Guardar. 6. Verificar ausencia de ruta. | H27: Ruta: RUT-QA-002 Pedido: PED-QA-002 Vehículo: VEH-QA-02 (No disponible) Piloto: PIL-QA-02 | I27: Rechaza asignación y no crea ruta activa. | J27: Pass | K27: 46294 | L27: Yefferson Valenzuela | M27: Se rechazó VEH-QA-02 por no estar disponible y no se creó una ruta activa. | N27: No registrado | O27: =J27 -> Pass | R27: No requería re-ejecución (sin defecto asociado).
A28: TC-REQ004-003 | B28: REQ004-B | C28: Kilometraje de llegada válido | D28: Partición de equivalencia | E28: Alta | F28: Ruta asignada; salida registrada. | G28: 1. Abrir ruta. 2. Consultar salida. 3. Ingresar llegada. 4. Guardar. 5. Revisar distancia. | H28: Ruta: RUT-QA-003 Salida: 15000 km Llegada: 15125 km Recorrido: 125 km | I28: Acepta llegada y registra recorrido de 125 km. | J28: Pass | K28: 46295 | L28: Yefferson Valenzuela | M28: Se aceptó la llegada de 15125 km frente a 15000 km de salida y se registró un recorrido de 125 km. | N28: No registrado | O28: =J28 -> Pass | R28: No requería re-ejecución (sin defecto asociado).
A29: TC-REQ004-004 | B29: REQ004-B | C29: Kilometraje de llegada igual a salida | D29: Análisis de valores límite | E29: Alta | F29: Ruta con salida registrada. | G29: 1. Abrir ruta. 2. Consultar salida. 3. Registrar misma llegada. 4. Guardar. 5. Revisar validación. | H29: Ruta: RUT-QA-004 Salida: 20000 km Llegada: 20000 km Diferencia: 0 | I29: Rechaza llegada porque debe ser estrictamente mayor. | J29: Pass | K29: 46297 | L29: Samuel Canastuj | M29: Se rechazó la llegada de 20000 km, igual a la salida de 20000 km, por no aumentar el kilometraje. | N29: No registrado | O29: =J29 -> Pass | R29: No requería re-ejecución (sin defecto asociado).
A30: TC-REQ004-005 | B30: REQ004-A | C30: Piloto con otra ruta activa | D30: Tabla de decisión | E30: Alta | F30: Piloto con ruta activa; vehículo nuevo disponible. | G30: 1. Abrir planificación. 2. Elegir nuevo pedido. 3. Elegir vehículo libre. 4. Elegir piloto ocupado. 5. Guardar. 6. Verificar asignaciones. | H30: Ruta existente: RUT-QA-005A Nueva: RUT-QA-005B Piloto: PIL-QA-03 (ocupado) Vehículo: VEH-QA-03 | I30: Impide segunda ruta activa para el mismo piloto. | J30: Pass | K30: 46300 | L30: Dennis Cornel | M30: Se impidió asignar PIL-QA-03 a RUT-QA-005B porque ya tenía activa RUT-QA-005A. | N30: No registrado | O30: =J30 -> Pass | R30: No requería re-ejecución (sin defecto asociado).
A31: TC-REQ004-006 | B31: REQ004-B | C31: Kilometraje de llegada inferior | D31: Análisis de valores límite | E31: Alta | F31: Ruta con salida registrada. | G31: 1. Abrir ruta. 2. Consultar salida. 3. Ingresar llegada inferior. 4. Guardar. 5. Revisar resultado. | H31: Ruta: RUT-QA-006 Salida: 20000 km Llegada: 19999 km Diferencia: −1 km | I31: Rechaza llegada y no almacena distancia negativa. | J31: Pass | K31: 46306 | L31: Samuel Canastuj | M31: Se rechazó la llegada de 19999 km frente a 20000 km de salida, sin almacenar una distancia negativa. | N31: No registrado | O31: =J31 -> Pass | R31: No requería re-ejecución (sin defecto asociado).
A32: TC-REQ004-007 | B32: REQ004-B | C32: Devolución con recepción física | D32: Transición de estados | E32: Alta | F32: Devolución reportada; usuario autorizado; estados por conciliar. | G32: 1. Abrir entrega. 2. Seleccionar devolución. 3. Registrar cantidad. 4. Confirmar recepción física. 5. Guardar. 6. Consultar trazabilidad. | H32: Ruta: RUT-QA-007 Producto: PROD-QA-01 Cantidad: 5 Recepción: Confirmada Resolución: Pendiente | I32: Registra recepción y trazabilidad; resolución pendiente. Nombre del estado por confirmar. | J32: Pass | K32: 46308 | L32: Yefferson Valenzuela | M32: Se registró la recepción de 5 unidades de PROD-QA-01 y quedó pendiente la resolución; nombre del estado por confirmar. | N32: No registrado | O32: =J32 -> Pass | R32: No requería re-ejecución (sin defecto asociado).
A33: TC-REQ004-008 | B33: REQ004-B | C33: Resolución sin recepción física | D33: Transición de estados | E33: Alta | F33: Devolución reportada sin recepción confirmada. | G33: 1. Abrir devoluciones. 2. Seleccionar registro. 3. Verificar recepción pendiente. 4. Solicitar reingreso. 5. Consultar inventario. | H33: Devolución: DEV-QA-008 Producto: PROD-QA-02 Cantidad: 8 Recepción: No confirmada Resolución: Reingreso | I33: Impide reingreso y no incrementa inventario. | J33: Pass | K33: 46311 | L33: Dennis Cornel | M33: Se bloqueó el reingreso de 8 unidades de PROD-QA-02 por falta de recepción física, sin aumentar el inventario. | N33: No registrado | O33: =J33 -> Pass | R33: No requería re-ejecución (sin defecto asociado).
A34: TC-REQ005-001 | B34: REQ005 | C34: Consulta con filtro de fechas | D34: Partición de equivalencia | E34: Alta | F34: Reporte accesible; datos QA fechados cargados. | G34: 1. Abrir reportes. 2. Elegir Producción. 3. Aplicar fechas. 4. Consultar. 5. Comparar registros. | H34: Reporte: Producción Inicio: 2026-10-01 Fin: 2026-10-07 Dentro: PROD-R01, PROD-R02 Fuera: PROD-R03 | I34: Incluye R01 y R02; excluye R03. | J34: Pass | K34: 46311 | L34: Dennis Cornel | M34: Ejecutado sobre el reporte de Pedidos (único reporte con filtro Desde/Hasta): el rango del 01 al 07/10/2026 incluyó los dos registros dentro del periodo y excluyó el registro fuera de rango. | N34: No registrado | O34: =J34 -> Pass | R34: No requería re-ejecución (sin defecto asociado).
A35: TC-REQ005-002 | B35: REQ005 | C35: Exportación PDF sin pérdida | D35: Partición de equivalencia | E35: Alta | F35: Reporte QA generado; exportación PDF disponible. | G35: 1. Abrir reporte. 2. Aplicar filtros. 3. Consultar. 4. Exportar PDF. 5. Abrir archivo. 6. Comparar filas y totales. | H35: Reporte: Producción Inicio: 2026-10-01 Fin: 2026-10-07 Registros: 2 Total: 150 kg Formato: PDF | I35: PDF conserva dos registros y total 150 kg. | J35: Pass | K35: 46314 | L35: Yefferson Valenzuela | M35: Ejecutado sobre el reporte de Pedidos: "Descargar PDF" generó el documento con los 2 registros filtrados y el total coincidente con la vista en pantalla. | N35: No registrado | O35: =J35 -> Pass | R35: No requería re-ejecución (sin defecto asociado).
A36: TC-REQ005-003 | B36: REQ005 | C36: Exportación Excel sin pérdida | D36: Partición de equivalencia | E36: Alta | F36: Reporte QA generado; exportación Excel disponible. | G36: 1. Abrir reporte. 2. Aplicar filtros. 3. Consultar. 4. Exportar Excel. 5. Abrir archivo. 6. Comparar filas y totales. | H36: Registros: PROD-R01 (100 kg), PROD-R02 (50 kg) Total: 150 kg Formato: Excel | I36: Excel conserva filas, cantidades y total de 150 kg. | J36: Fail | K36: 46314 | L36: Samuel Canastuj | M36: Ningún reporte del sistema ofrece exportación a Excel; solo existe "Descargar PDF". No es posible obtener el archivo .xlsx esperado. | N36: BUG-REP-01 | O36: Pass | P36: 46315 | Q36: Samuel Canastuj | R36: Re-ejecutado: "Descargar Excel" generó reporte_pedidos_2026-10-01_2026-10-31.xlsx; abre en Excel con 4 hojas, cantidades por producto idénticas a la pantalla y total Q1,614.00 igual al resumen.
A37: TC-REQ005-004 | B37: REQ005 | C37: Intervalo de fechas inválido | D37: Análisis de valores límite | E37: Alta | F37: Formulario de filtros disponible. | G37: 1. Abrir reportes. 2. Elegir reporte. 3. Ingresar inicio posterior a fin. 4. Consultar. 5. Revisar validación. | H37: Inicio: 2026-10-15 Fin: 2026-10-10 | I37: Rechaza intervalo invertido; regla propuesta por confirmar. | J37: Fail | K37: 46315 | L37: Dennis Cornel | M37: La pantalla de Pedidos sí rechaza "Desde" posterior a "Hasta", pero la API GET /api/pedidos/reportes/* con desde=2026-10-15 y hasta=2026-10-10 respondió HTTP 200 con lista vacía, sin error de validación. La búsqueda avanzada de Trazabilidad tampoco valida el rango. | N37: BUG-REP-02 | O37: Pass | P37: 46315 | Q37: Dennis Cornel | R37: Re-ejecutado: la API responde HTTP 400 en reportes de pedidos y trazabilidad, y la pantalla de Trazabilidad muestra el aviso; un rango de un solo día sigue aceptándose.
A38: TC-REQ005-005 | B38: REQ005 | C38: Filtros combinados de fecha, cliente y merma | D38: Pairwise | E38: Alta | F38: Datos QA con clientes, fechas y mermas; filtros disponibles. | G38: 1. Abrir reporte de mermas. 2. Elegir período. 3. Elegir cliente. 4. Elegir tipo de merma. 5. Consultar. 6. Comparar coincidencias. | H38: Inicio: 2026-10-01 Fin: 2026-10-07 Cliente: CLI-QA-01 Merma: Pelado Coincide: MER-QA-01 No coincide: MER-QA-02 | I38: Solo muestra registros que cumplen los tres filtros. Variantes PW01–PW04 pendientes de resultados específicos. | J38: Skipped | K38: 46315 | L38: Samuel Canastuj | M38: No ejecutado: ningún reporte del sistema combina los filtros de fecha, cliente y tipo de merma, por lo que el caso y sus variantes Pairwise PW01–PW04 quedan fuera del alcance de esta versión por decisión del equipo; se conservan para una versión futura. | N38: N/A – fuera de alcance | O38: =J38 -> Skipped | R38: No requería re-ejecución (sin defecto asociado).
